Workbook

Sheet Feedback data sheet
A1: ID | B1: Start Time | C1: Name | D1: If your feedback requires further action from us, such as an incomplete piece of work, please provide your email address below so that we can get back to you. | E1: Where was the work located? | F1: What type of work are you providing feedback on? | G1: Please provide us with more information on what you requested our help with. This is especially helpful if you do not have a reference number, or if you selected "other" for question 4. | H1: When did you make the request | I1: Were you satisfied with the time it took to complete the work? | J1: In your opinion, please rate out of 5 how committed our team were to delivering outstanding customer service? | K1: Please provide us with any other feedback in your own words here. | L1: How likely are you to recommend this service to others at King's?
A2: 1 | B2: 44930.362 | C2: Dorothy Gale | E2: Strand Campus - all buildings, including Virginia Woolf & Maughan Library | F2: Cleaning | G2: Carpet cleaning post furniture removal. | H2: 44914 | I2: Yes | J2: 5 | K2: The team did a great job in a very timely manner. Many thanks! | L2: 10
A3: 2 | B3: 44932.441 | C3: Bella Papa | E3: Waterloo Campus - James Clerk Maxwell & Waterloo Bridge Wing | F3: Soft Services (e.g. moving furniture, room set up, WEEE collection, pest control, internal deliveries between campuses etc.) | G3: I asked for computer monitors to be moved to Bush House | H3: 44931 | I3: Yes | J3: 5 | K3: Excellent Service! The monitors arrived on 1/6/2023 | L3: 10
A4: 3 | B4: 44939.532 | C4: Dez Yorna | E4: Denmark Hill Campus | F4: Soft Services (e.g. moving furniture, room set up, WEEE collection, pest control, internal deliveries between campuses etc.) | G4: Removal of old equipment | H4: 44938 | I4: Yes | J4: 5 | K4: Quick and efficient removal of equipment. Couldn't be bettered | L4: 10
A5: 4 | B5: 44945.486 | C5: Aydin Anderson | E5: Strand Campus - all buildings, including Virginia Woolf & Maughan Library | F5: Hard services (e.g. lighting, plumbing, decorating, heating/cooling, fabrics etc.) | G5: Repair of a lavatory seat in disabled loo -1.16 | H5: 44943 | I5: Yes | J5: 5 | K5: I was pleasantly surprised to find that the loo seat had been replaced the day after I put in the ticket. Reamarkably quick work. | L5: 10
A6: 5 | B6: 44946.629 | C6: Ike West | E6: Guy's Campus - all buildings except New Hunts House | F6: Soft Services (e.g. moving furniture, room set up, WEEE collection, pest control, internal deliveries between campuses etc.) | G6: Collection of cage of poster boards. | H6: 44945 | I6: Yes | J6: 5 | L6: 10
A7: 6 | B7: 44949.649 | C7: Mulan Hua | E7: Guy's Campus - all buildings except New Hunts House | F7: Hard services (e.g. lighting, plumbing, decorating, heating/cooling, fabrics etc.) | G7: Broken Toilet | H7: 44942 | I7: No | J7: 2 | K7: No response or feedback received til 3 days after submitting the request | L7: 2
A8: 7 | B8: 44950.889 | C8: David Sergant | E8: Strand Campus - all buildings, including Virginia Woolf & Maughan Library | F8: Hard services (e.g. lighting, plumbing, decorating, heating/cooling, fabrics etc.) | G8: Ventilation in Study Café rooms for the Geography Department. | H8: 45266 | I8: No | J8: 2 | K8: It shouldn't take almost two months to check the ventilation of 3 rooms. | L8: 5
A9: 8 | B9: 44951.613 | C9: Fred Waltz | E9: Guy's Campus - all buildings except New Hunts House | F9: Hard services (e.g. lighting, plumbing, decorating, heating/cooling, fabrics etc.) | G9: I requested that the heating in a lecture theatre be turned up as the room was too cold | H9: 44946 | I9: No | J9: 5 | K9: I did not feel a difference in temperature while I was in there, perhaps the room needed longer to warm up | L9: 10
A10: 9 | B10: 44952.62 | C10: Jenny Birmingham | D10: Yes | E10: Strand Campus - all buildings, including Virginia Woolf & Maughan Library | F10: Hard services (e.g. lighting, plumbing, decorating, heating/cooling, fabrics etc.) | G10: I often cycle to Bush House and then shower. I shower at the gym once a week as well, and I find the water temperature just a bit too cold. I know it’s important to save energy, so I feel bad for asking, but could you turn the water heat up by just a degree or two? I don’t want to be shivering in the shower anymore! | H10: 44950 | I10: Yes | J10: 3 | L10: 7
A11: 10 | B11: 44956.39 | C11: Selma Grant | D11: n/a | E11: Strand Campus - all buildings, including Virginia Woolf & Maughan Library | F11: Hard services (e.g. lighting, plumbing, decorating, heating/cooling, fabrics etc.) | G11: addressing foul smell in women's toilets -- plumbing or cleaning problem which had last more than a month. | H11: 44950 | I11: Yes | J11: 5 | K11: Very prompt response; successful resolution to a long-standing problem affecting all women on S8 | L11: 10
A12: 11 | B12: 44958.593 | C12: Zane Chu | D12: No | E12: Strand Campus - all buildings, including Virginia Woolf & Maughan Library | F12: Hard services (e.g. lighting, plumbing, decorating, heating/cooling, fabrics etc.) | G12: Power cut off in the cafe | H12: 44958 | I12: Yes | J12: 5 | K12: Power cut of in our one of cafe. Team arrived very quickly and solved the problem | L12: 10
A13: 12 | B13: 44959.42 | C13: Warren Tracey | D13: N/A | E13: Guy's Campus - all buildings except New Hunts House | F13: Soft Services (e.g. moving furniture, room set up, WEEE collection, pest control, internal deliveries between campuses etc.) | G13: Empty Confidential Waste Bin | H13: 44957 | I13: Yes | J13: 5 | K13: Excellent Service as ever by Facilities team, Thank you | L13: 10
A14: 13 | B14: 44959.586 | C14: Ron Tempernillo | E14: Strand Campus - all buildings, including Virginia Woolf & Maughan Library | F14: Hard services (e.g. lighting, plumbing, decorating, heating/cooling, fabrics etc.) | G14: The radiator wasn't heating up efficiently, meaning that my office only ever came to 15 degrees centigrade and no higher. I was doing meetings in my coat and hat! It seems to be sorted now, so thanks a million - lifesavers! | H14: 44935 | I14: Yes | J14: 5 | K14: I didn't receive any ongoing updates as to the progression of the case, which might have been useful. Moreover, it seems to have been fixed, because one day I entered the office and found it fully functional, but I had to discover this for myself. A little bit more constant communication would have been beneficial, but overall I'm highly satisfied. Thank you. | L14: 8
A15: 14 | B15: 44960.472 | C15: Peter Parker | E15: Guy's Campus - all buildings except New Hunts House | F15: Soft Services (e.g. moving furniture, room set up, WEEE collection, pest control, internal deliveries between campuses etc.) | G15: Electrical waste collection | H15: 44956 | I15: Yes | J15: 4 | L15: 7
A16: 15 | B16: 44964.658 | C16: Ryan Burke | E16: Strand Campus - all buildings, including Virginia Woolf & Maughan Library | F16: Hard services (e.g. lighting, plumbing, decorating, heating/cooling, fabrics etc.) | G16: Lights not working | H16: 44964 | I16: Yes | J16: 5 | K16: The team was fantastic. I was really impressed with how quickly they came back to request more details, and then came to fix the problem. | L16: 10
A17: 16 | B17: 44964.68 | C17: Anthony Alan | D17: Yes | E17: Guy's Campus - all buildings except New Hunts House | F17: Hard services (e.g. lighting, plumbing, decorating, heating/cooling, fabrics etc.) | G17: Please confirm the engineering comments / what was actually done and when in relation to my request. My request was in relation to a H&S issue thus I require a record of suitable timely response. | H17: 44889 | I17: Yes | J17: 3 | K17: Comments of how the job was complete should be standard in the closing ticket email. | L17: 7
A18: 17 | B18: 44965.59 | C18: David Sergant | E18: Waterloo Campus - James Clerk Maxwell & Waterloo Bridge Wing | F18: Soft Services (e.g. moving furniture, room set up, WEEE collection, pest control, internal deliveries between campuses etc.) | G18: New window blind fitted | H18: 44901 | I18: No | J18: 3 | K18: I had to chase up 3 times. | L18: 7
A19: 18 | B19: 44966.523 | C19: Elaine Hertz | D19: Yes | E19: Strand Campus - all buildings, including Virginia Woolf & Maughan Library | F19: Hard services (e.g. lighting, plumbing, decorating, heating/cooling, fabrics etc.) | G19: Two lights not working; one is on a very high ceiling that requires scaffolding | H19: 44887 | I19: No | J19: 3 | K19: Lower light was fixed; someone came to assess for scaffolding and said it would be done before Christmas in the quieter period, but the work hasn't been done and the ticket is closed. | L19: 6
A20: 19 | B20: 44971.619 | C20: Anthony Alan | E20: Denmark Hill Campus | F20: Hard services (e.g. lighting, plumbing, decorating, heating/cooling, fabrics etc.) | G20: Plumbing | H20: 44964 | I20: Yes | J20: 5 | L20: 10
A21: 20 | B21: 44973.513 | C21: Ha-Hei Long | E21: Denmark Hill Campus | F21: Hard services (e.g. lighting, plumbing, decorating, heating/cooling, fabrics etc.) | G21: fixing up new hooks for lab coats in main lab | H21: 44971 | I21: Yes | J21: 4 | K21: gereat stuff - all done really quickly thanks | L21: 8
A22: 21 | B22: 44974.544 | C22: Oliver Marks | E22: Strand Campus - all buildings, including Virginia Woolf & Maughan Library | F22: Soft Services (e.g. moving furniture, room set up, WEEE collection, pest control, internal deliveries between campuses etc.) | G22: Desk moves. | H22: 44971 | I22: Yes | J22: 5 | K22: Work completed quickly and efficiently - many thanks! | L22: 10
A23: 22 | B23: 44978.529 | C23: Laila Stone | E23: Guy's Campus - all buildings except New Hunts House | F23: Soft Services (e.g. moving furniture, room set up, WEEE collection, pest control, internal deliveries between campuses etc.) | G23: WEEE removal | H23: 44964 | I23: Yes | J23: 5 | L23: 10
A24: 23 | B24: 44978.638 | C24: Anthony Alan | E24: Strand Campus - all buildings, including Virginia Woolf & Maughan Library | F24: Hard services (e.g. lighting, plumbing, decorating, heating/cooling, fabrics etc.) | G24: Leaky water fountain | H24: 44960 | I24: Yes | J24: 5 | K24: Would be great to get more information about the way the problem was solved, what dificulties were faced and how it has influenced long term policy. I've noticed that there may be other water fountains with the same issue, have they been reviewed? how did you fix it? Was it a one off or can we expect hits problem to continue happening? etc | L24: 10
A25: 24 | B25: 44985.403 | C25: Eli Bruce | D25: Yes | E25: Strand Campus - all buildings, including Virginia Woolf & Maughan Library | F25: Hard services (e.g. lighting, plumbing, decorating, heating/cooling, fabrics etc.) | G25: Handrail on steps is wobbly | H25: 44963 | I25: No | J25: 1 | K25: The ticket has been marked as 'completed' but the handrail is still wobbly. | L25: 3
A26: 25 | B26: 44986.489 | C26: Chanel Hubbard | E26: Waterloo Campus - James Clerk Maxwell & Waterloo Bridge Wing | F26: Cleaning | G26: The request was for removal of bulk general waste as I am clearing my office. | H26: 44985 | I26: Yes | J26: 5 | K26: The service was so efficient and smooth. THank you. | L26: 10
A27: 26 | B27: 44987.601 | C27: Laila Stone | D27: Yes | E27: Guy's Campus - all buildings except New Hunts House | F27: Hard services (e.g. lighting, plumbing, decorating, heating/cooling, fabrics etc.) | G27: The fire exit sign above the door to this workspace had been knocked off by the door that opens into it. We could not reattach it to the ceiling. | H27: 44985 | I27: Yes | J27: 5 | K27: Very good. The sign is now reattached. | L27: 8
A28: 27 | B28: 44992.711 | C28: Kat Wallace | E28: Strand Campus - all buildings, including Virginia Woolf & Maughan Library | F28: Hard services (e.g. lighting, plumbing, decorating, heating/cooling, fabrics etc.) | G28: Lights not working in the Anatomy Museum K6.36 | H28: 44987 | I28: Yes | J28: 5 | K28: The team went above and beyond to make sure that the lights were working properly very soon after I reported it. This meant that our performances could go ahead and the audience were very happy. Thanks very much to Robson and the whole team. | L28: 10
A29: 28 | B29: 44993.432 | C29: Kim Li | E29: Strand Campus - all buildings, including Virginia Woolf & Maughan Library | F29: Soft Services (e.g. moving furniture, room set up, WEEE collection, pest control, internal deliveries between campuses etc.) | G29: Furniture removal and temporary storage ahead of refurbishment works | H29: 44991 | I29: Yes | J29: 5 | K29: Edwar and the team went above and beyond on this job, many thanks! | L29: 10
A30: 29 | B30: 44999.542 | C30: Anthony Alan | E30: Guy's Campus - all buildings except New Hunts House | F30: Hard services (e.g. lighting, plumbing, decorating, heating/cooling, fabrics etc.) | G30: Fix leak from ceiling | H30: 44994 | I30: Yes | J30: 4 | K30: It would be good when engineers came to look into the problem to contact us so someone is on site and in person to ask questions and understand the issue during it is being looked at and fixed so potentially we can also fix the issue oursleves and understand what caused the problem better for next time. | L30: 9
A31: 30 | B31: 45001.437 | C31: Ed Salter | E31: Denmark Hill Campus | F31: Cleaning | G31: Carpet deep cleaning | H31: 45000 | I31: Yes | J31: 5 | K31: Job well done and on time | L31: 9
A32: 32 | B32: 45001.581 | C32: Tracey Darren | E32: Guy's Campus - all buildings except New Hunts House | F32: Hard services (e.g. lighting, plumbing, decorating, heating/cooling, fabrics etc.) | G32: Fixing house lights in the Science Gallery Theatre | H32: 44980 | I32: Yes | J32: 5 | K32: Brilliant fix from the electrical guys - thank you | L32: 10
A33: 33 | B33: 45005.465 | C33: Sean Stewart | E33: Strand Campus - all buildings, including Virginia Woolf & Maughan Library | F33: Cleaning | G33: A disabled toilet was blocked and overflowed. | H33: 45001 | I33: Yes | J33: 4 | K33: I saw a member of staff going to clear the bathroom within a short amount of time. | L33: 9
A34: 34 | B34: 45012.824 | C34: Sheila Oz | E34: Denmark Hill Campus | F34: Hard services (e.g. lighting, plumbing, decorating, heating/cooling, fabrics etc.) | G34: Put up item (noticeboard/whiteboard/hooks etc) | H34: 44855 | I34: Yes | J34: 5 | K34: Delay was not due to Estates but after the first visit, we realised the work was more involved and we have to purchase a new picture frames before Estates ciould complete the job. Overall, we are very satisfied.t | L34: 10
A35: 35 | B35: 45013.711 | C35: Erin Watts | E35: Waterloo Campus - James Clerk Maxwell & Waterloo Bridge Wing | F35: Cleaning | G35: At present I am clearing my office. Estates and facilities are helping enormously with the disposal of certain items, including confidential waste. | H35: 45008 | I35: Yes | J35: 5 | K35: It is so helpful to have this professional, efficient support from Estates and Facilities. Thank you. | L35: 10
A36: 36 | B36: 45014.76 | C36: Sheila Oz | E36: Guy's Campus - all buildings except New Hunts House | F36: Cleaning | G36: Empty sanitary dispenser | H36: 45013 | I36: Yes | J36: 4 | K36: Very quick response via email. Received an update once the request had been completed | L36: 8
A37: 37 | B37: 45015.343 | C37: Lorna Chills | E37: Guy's Campus - all buildings except New Hunts House | F37: Security | G37: I noticed a door closer was broken and hanging loose and so when the door was opened, it would swing shut onto the broken bit preventing it from closing securely and locking, so this was a security risk as it meant the door could not guarantee to close completely and was just beeping. | H37: 45012 | I37: Yes | J37: 4 | K37: I dislike the way that my ticket is resolved with absolutely no information about what was done to resolve it. I should see some resolution description about what was done eg 'door lock was replaced/broken glass was replaced, door was locked while we wait for access to be protected etc etc'. I am glad my query was dealt with quickly but I want to see what was actually done in my ticket resolution please. | L37: 5
A38: 38 | B38: 45015.406 | C38: Ben Wills | E38: Strand Campus - all buildings, including Virginia Woolf & Maughan Library | F38: Hard services (e.g. lighting, plumbing, decorating, heating/cooling, fabrics etc.) | G38: Making an additional key | H38: 44986 | I38: No | J38: 3 | K38: I am grateful to receive the key, and communications from Estates have been helpful, but I was surprised that it took 20 working days to produce a key (as were King's security!). Qu. 10 below seems to me to be irrelevant as I understood that the key had to be manufactured by King's Estates. | L38: 5
A39: 39 | B39: 45021.617 | C39: Chang Moon | E39: Denmark Hill Campus | F39: Hard services (e.g. lighting, plumbing, decorating, heating/cooling, fabrics etc.) | G39: put up new key holders 3rd floor | H39: 45019 | I39: Yes | J39: 4 | K39: great response time thank you | L39: 9
... A41: 41 | B41: 45027.53 | C41: Val Wright | E41: Denmark Hill Campus | F41: Hard services (e.g. lighting, plumbing, decorating, heating/cooling, fabrics etc.) | G41: Lift Remedial | H41: 45020 | I41: Yes | J41: 5 | K41: Excellent | L41: 10
...

Sheet Tables
C3: Using the provided Excel spreadsheet containing mock customer feedback, please create a PowerPoint presentation consisting of three slides.
C4: Please consider the information through the data presented with a focus to highlight
D5: 1 | E5: how the data can be improved and
D6: 2 | E6: how the data can be used to improve customer service in Estates and Facilities
C7: Also include a clear introduction with outline, presentation of data and summary of your points.
B10: =68/117 -> 0.58119658 | C10: Name | D10: # | E10: Where was the work located? | F10: # | G10: What type of work are you providing feedback on? | H10: # | I10: % | J10: Were you satisfied with the time it took to complete the work? | K10: # | L10: how committed our team were to delivering outstanding customer service? | M10: # | N10: How likely are you to recommend this service to others at King's? | O10: #
C11: Abby Smith | D11: =COUNTIFS('Feedback data sheet'!C:C,C11) -> 1 | E11: A King's Residence | F11: =COUNTIFS('Feedback data sheet'!E:E,E11) -> 6 | G11: Cleaning | H11: =COUNTIFS('Feedback data sheet'!F:F,G11) -> 14 | I11: =H11/117 -> 0.11965812 | J11: No | K11: =COUNTIFS('Feedback data sheet'!I:I,J11) -> 21 | L11: 1 | M11: =COUNTIFS('Feedback data sheet'!J:J,L11) -> 12 | N11: 1 | O11: =COUNTIFS('Feedback data sheet'!L:L,N11) -> 9 | P11: =O11/117 -> 0.076923077
C12: Andy Chan | D12: =COUNTIFS('Feedback data sheet'!C:C,C12) -> 1 | E12: Denmark Hill Campus | F12: =COUNTIFS('Feedback data sheet'!E:E,E12) -> 29 | G12: Hard services (e.g. lighting, plumbing, decorating, heating/cooling, fabrics etc.) | H12: =COUNTIFS('Feedback data sheet'!F:F,G12) -> 69 | I12: =H12/117 -> 0.58974359 | J12: Yes | K12: =COUNTIFS('Feedback data sheet'!I:I,J12) -> 96 | L12: 2 | M12: =COUNTIFS('Feedback data sheet'!J:J,L12) -> 4 | N12: 2 | O12: =COUNTIFS('Feedback data sheet'!L:L,N12) -> 2 | P12: =O12/117 -> 0.017094017
C13: Anthony Alan | D13: =COUNTIFS('Feedback data sheet'!C:C,C13) -> 8 | E13: Guy's Campus - all buildings except New Hunts House | F13: =COUNTIFS('Feedback data sheet'!E:E,E13) -> 33 | G13: Residences - Applications | H13: =COUNTIFS('Feedback data sheet'!F:F,G13) -> 2 | I13: =H13/117 -> 0.017094017 | K13: =K12/SUM(K11:K12) -> 0.82051282 | L13: 3 | M13: =COUNTIFS('Feedback data sheet'!J:J,L13) -> 7 | N13: 3 | O13: =COUNTIFS('Feedback data sheet'!L:L,N13) -> 2 | P13: =O13/117 -> 0.017094017
C14: Atlas Steel | D14: =COUNTIFS('Feedback data sheet'!C:C,C14) -> 1 | E14: Guy's Campus - New Hunts House | F14: =COUNTIFS('Feedback data sheet'!E:E,E14) -> 3 | G14: Residences - In House Service | H14: =COUNTIFS('Feedback data sheet'!F:F,G14) -> 3 | I14: =H14/117 -> 0.025641026 | L14: 4 | M14: =COUNTIFS('Feedback data sheet'!J:J,L14) -> 13 | N14: 4 | O14: =COUNTIFS('Feedback data sheet'!L:L,N14) -> 2 | P14: =O14/117 -> 0.017094017
C15: Aydin Anderson | D15: =COUNTIFS('Feedback data sheet'!C:C,C15) -> 2 | E15: St Thomas's Campus | F15: =COUNTIFS('Feedback data sheet'!E:E,E15) -> 1 | G15: Security | H15: =COUNTIFS('Feedback data sheet'!F:F,G15) -> 1 | I15: =H15/117 -> 0.0085470085 | L15: 5 | M15: =COUNTIFS('Feedback data sheet'!J:J,L15) -> 81 | N15: 5 | O15: =COUNTIFS('Feedback data sheet'!L:L,N15) -> 4 | P15: =O15/117 -> 0.034188034
C16: Barbara Benneditto | D16: =COUNTIFS('Feedback data sheet'!C:C,C16) -> 1 | E16: Strand Campus - all buildings, including Virginia Woolf & Maughan Library | F16: =COUNTIFS('Feedback data sheet'!E:E,E16) -> 35 | G16: Soft Services (e.g. moving furniture, room set up, WEEE collection, pest control, internal deliveries between campuses etc.) | H16: =COUNTIFS('Feedback data sheet'!F:F,G16) -> 28 | I16: =H16/117 -> 0.23931624 | M16: =M15/117 -> 0.69230769 | N16: 6 | O16: =COUNTIFS('Feedback data sheet'!L:L,N16) -> 1 | P16: =O16/117 -> 0.0085470085
C17: Bella Papa | D17: =COUNTIFS('Feedback data sheet'!C:C,C17) -> 2 | E17: Waterloo Campus - Franklin Wilkins Building | F17: =COUNTIFS('Feedback data sheet'!E:E,E17) -> 2 | N17: 7 | O17: =COUNTIFS('Feedback data sheet'!L:L,N17) -> 4 | P17: =O17/117 -> 0.034188034
C18: Ben Wills | D18: =COUNTIFS('Feedback data sheet'!C:C,C18) -> 2 | E18: Waterloo Campus - James Clerk Maxwell & Waterloo Bridge Wing | F18: =COUNTIFS('Feedback data sheet'!E:E,E18) -> 8 | N18: 8 | O18: =COUNTIFS('Feedback data sheet'!L:L,N18) -> 7 | P18: =O18/117 -> 0.05982906 | R18: =SUM(P11:P16) -> 0.17094017 | S18: 0 -6
C19: Bernie McGill | D19: =COUNTIFS('Feedback data sheet'!C:C,C19) -> 1 | N19: 9 | O19: =COUNTIFS('Feedback data sheet'!L:L,N19) -> 8 | P19: =O19/117 -> 0.068376068 | R19: =P19+P20 -> 0.73504274 | S19: 9 -10
C20: Bic Runga | D20: =COUNTIFS('Feedback data sheet'!C:C,C20) -> 1 | N20: 10 | O20: =COUNTIFS('Feedback data sheet'!L:L,N20) -> 78 | P20: =O20/117 -> 0.66666667 | R20: =R19-R18 -> 0.56410256 | S20: NPS
C21: Bo Runga | D21: =COUNTIFS('Feedback data sheet'!C:C,C21) -> 1
C22: Bruce Wayne | D22: =COUNTIFS('Feedback data sheet'!C:C,C22) -> 1
C23: Caz West | D23: =COUNTIFS('Feedback data sheet'!C:C,C23) -> 1
C24: Chanel Hubbard | D24: =COUNTIFS('Feedback data sheet'!C:C,C24) -> 2
C25: Chang Moon | D25: =COUNTIFS('Feedback data sheet'!C:C,C25) -> 2
C26: Claire Bale | D26: =COUNTIFS('Feedback data sheet'!C:C,C26) -> 1
C27: Claire King | D27: =COUNTIFS('Feedback data sheet'!C:C,C27) -> 2
C28: Dan Ivanovich | D28: =COUNTIFS('Feedback data sheet'!C:C,C28) -> 1
C29: David Sergant | D29: =COUNTIFS('Feedback data sheet'!C:C,C29) -> 4
C30: Dean Hoki | D30: =COUNTIFS('Feedback data sheet'!C:C,C30) -> 1
C31: Dez Yorna | D31: =COUNTIFS('Feedback data sheet'!C:C,C31) -> 2
C32: Dipak Patel | D32: =COUNTIFS('Feedback data sheet'!C:C,C32) -> 1
... C78: Zoe Liu | D78: =COUNTIFS('Feedback data sheet'!C:C,C78) -> 1

Sheet Pivots
A3: Count of ID | B3: Column Labels
A4: Row Labels | B4: 1 | C4: 2 | D4: 3 | E4: 4 | F4: 5 | G4: Grand Total
A5: Cleaning | B5: 1 | D5: 1 | E5: 3 | F5: 9 | G5: 14 | I5: =F5/G5 -> 0.64285714
A6: Hard services (e.g. lighting, plumbing, decorating, heating/cooling, fabrics etc.) | B6: 11 | C6: 4 | D6: 5 | E6: 8 | F6: 41 | G6: 69 | I6: =F6/G6 -> 0.5942029 | L6: =11/69 -> 0.15942029
A7: Residences - Applications | F7: 2 | G7: 2 | I7: =F7/G7 -> 1
A8: Residences - In House Service | F8: 3 | G8: 3 | I8: =F8/G8 -> 1
A9: Security | E9: 1 | G9: 1 | I9: =F9/G9 -> 0
A10: Soft Services (e.g. moving furniture, room set up, WEEE collection, pest control, internal deliveries between campuses etc.) | D10: 1 | E10: 1 | F10: 26 | G10: 28 | I10: =F10/G10 -> 0.92857143
A11: Grand Total | B11: 12 | C11: 4 | D11: 7 | E11: 13 | F11: 81 | G11: 117 | I11: =F11/G11 -> 0.69230769
A16: Service | B16: No | C16: Yes
A17: Cleaning | B17: 1 | C17: 13
A18: Hard services | B18: 19 | C18: 50
A19: Residences - Applications | C19: 2
A20: Residences - In House Service | C20: 3
A21: Security | C21: 1
A22: Soft Services | B22: 1 | C22: 27
A35: Count of ID | B35: Column Labels
A36: Row Labels | B36: 1 | C36: 2 | D36: 3 | E36: 4 | F36: 5 | G36: 6 | H36: 7 | I36: 8 | J36: 9 | K36: 10 | L36: Grand Total | O36: 0 -6 | P36: 9 -10 | Q36: NPS
A37: Cleaning | B37: 1 | I37: 2 | J37: 2 | K37: 9 | L37: 14 | N37: Cleaning | O37: =-(SUM(B37:G37)/L37)*100 -> -7.1428571 | P37: =(SUM(J37:K37)/L37)*100 -> 78.571429 | Q37: =P37+O37 -> 71.428571
A38: Hard services (e.g. lighting, plumbing, decorating, heating/cooling, fabrics etc.) | B38: 8 | C38: 2 | D38: 2 | E38: 2 | F38: 3 | G38: 1 | H38: 2 | I38: 4 | J38: 5 | K38: 40 | L38: 69 | N38: Hard services | O38: =-(SUM(B38:G38)/L38)*100 -> -26.086957 | P38: =(SUM(J38:K38)/L38)*100 -> 65.217391 | Q38: =P38+O38 -> 39.130435
A39: Residences - Applications | K39: 2 | L39: 2 | N39: Residences - Applications | O39: =-(SUM(B39:G39)/L39)*100 -> 0 | P39: =(SUM(J39:K39)/L39)*100 -> 100 | Q39: =P39+O39 -> 100
A40: Residences - In House Service | K40: 3 | L40: 3 | N40: Residences - In House Service | O40: =-(SUM(B40:G40)/L40)*100 -> 0 | P40: =(SUM(J40:K40)/L40)*100 -> 100 | Q40: =P40+O40 -> 100
A41: Security | F41: 1 | L41: 1 | N41: Security | O41: =-(SUM(B41:G41)/L41)*100 -> -100 | P41: =(SUM(J41:K41)/L41)*100 -> 0 | Q41: =P41+O41 -> -100
A42: Soft Services (e.g. moving furniture, room set up, WEEE collection, pest control, internal deliveries between campuses etc.) | H42: 2 | I42: 1 | J42: 1 | K42: 24 | L42: 28 | N42: Soft Services | O42: =-(SUM(B42:G42)/L42)*100 -> 0 | P42: =(SUM(J42:K42)/L42)*100 -> 89.285714 | Q42: =P42+O42 -> 89.285714
A43: Grand Total | B43: 9 | C43: 2 | D43: 2 | E43: 2 | F43: 4 | G43: 1 | H43: 4 | I43: 7 | J43: 8 | K43: 78 | L43: 117 | O43: =-(SUM(B43:G43)/L43)*100 -> -17.094017 | P43: =(SUM(J43:K43)/L43)*100 -> 73.504274 | Q43: =P43+O43 -> 56.410256
